<?xml version="1.0" ?>
<robot name="HandBot">

<link name="base_link">
  <inertial>
    <origin xyz="0.05828589570831179 -0.017233303202980166 -1.0569907835876657" rpy="0 0 0"/>
    <mass value="200.8271220404809"/>
    <inertia ixx="5.540602" iyy="3.257941" izz="8.417032" ixy="0.002781" iyz="-0.010989" ixz="0.006943"/>
  </inertial>
  <visual>
    <origin xyz="0 0 0" rpy="0 0 0"/>
    <geometry>
      <mesh filename="meshes/base_link.stl" scale="0.001 0.001 0.001"/>
    </geometry>
    <material name="silver"/>
  </visual>
  <collision>
    <origin xyz="0 0 0" rpy="0 0 0"/>
    <geometry>
      <mesh filename="meshes/base_link.stl" scale="0.001 0.001 0.001"/>
    </geometry>
  </collision>
</link>

<link name="pinky_b_1">
  <inertial>
    <origin xyz="-0.0006875437725173562 1.734723475976807e-18 0.0026067773102528696" rpy="0 0 0"/>
    <mass value="0.037507074361311475"/>
    <inertia ixx="2e-06" iyy="2e-06" izz="2e-06" ixy="0.0" iyz="-0.0" ixz="0.0"/>
  </inertial>
  <visual>
    <origin xyz="-0.009534 -0.01 -0.107216" rpy="0 0 0"/>
    <geometry>
      <mesh filename="meshes/pinky_b_1.stl" scale="0.001 0.001 0.001"/>
    </geometry>
    <material name="silver"/>
  </visual>
  <collision>
    <origin xyz="-0.009534 -0.01 -0.107216" rpy="0 0 0"/>
    <geometry>
      <mesh filename="meshes/pinky_b_1.stl" scale="0.001 0.001 0.001"/>
    </geometry>
  </collision>
</link>

<link name="ring_b_1">
  <inertial>
    <origin xyz="-0.0011280549931480532 1.734723475976807e-18 0.010207260307445176" rpy="0 0 0"/>
    <mass value="0.07459720648244657"/>
    <inertia ixx="9e-06" iyy="9e-06" izz="4e-06" ixy="0.0" iyz="-0.0" ixz="1e-06"/>
  </inertial>
  <visual>
    <origin xyz="-0.033736 -0.01 -0.123168" rpy="0 0 0"/>
    <geometry>
      <mesh filename="meshes/ring_b_1.stl" scale="0.001 0.001 0.001"/>
    </geometry>
    <material name="silver"/>
  </visual>
  <collision>
    <origin xyz="-0.033736 -0.01 -0.123168" rpy="0 0 0"/>
    <geometry>
      <mesh filename="meshes/ring_b_1.stl" scale="0.001 0.001 0.001"/>
    </geometry>
  </collision>
</link>

<link name="middle_b_1">
  <inertial>
    <origin xyz="0.0008388761543654394 5.377642775528102e-15 0.01278695435703378" rpy="0 0 0"/>
    <mass value="0.08725974909093531"/>
    <inertia ixx="1.3e-05" iyy="1.3e-05" izz="5e-06" ixy="-0.0" iyz="-0.0" ixz="-1e-06"/>
  </inertial>
  <visual>
    <origin xyz="-0.054177 -0.01 -0.128125" rpy="0 0 0"/>
    <geometry>
      <mesh filename="meshes/middle_b_1.stl" scale="0.001 0.001 0.001"/>
    </geometry>
    <material name="silver"/>
  </visual>
  <collision>
    <origin xyz="-0.054177 -0.01 -0.128125" rpy="0 0 0"/>
    <geometry>
      <mesh filename="meshes/middle_b_1.stl" scale="0.001 0.001 0.001"/>
    </geometry>
  </collision>
</link>

<link name="index_b_1">
  <inertial>
    <origin xyz="0.00200559484297054 -3.469446951953614e-16 0.010064739753064142" rpy="0 0 0"/>
    <mass value="0.07457904216380486"/>
    <inertia ixx="9e-06" iyy="9e-06" izz="4e-06" ixy="0.0" iyz="0.0" ixz="-1e-06"/>
  </inertial>
  <visual>
    <origin xyz="-0.076931 -0.01 -0.123298" rpy="0 0 0"/>
    <geometry>
      <mesh filename="meshes/index_b_1.stl" scale="0.001 0.001 0.001"/>
    </geometry>
    <material name="silver"/>
  </visual>
  <collision>
    <origin xyz="-0.076931 -0.01 -0.123298" rpy="0 0 0"/>
    <geometry>
      <mesh filename="meshes/index_b_1.stl" scale="0.001 0.001 0.001"/>
    </geometry>
  </collision>
</link>

<link name="pinky_m_1">
  <inertial>
    <origin xyz="-0.0013004130573036525 3.469446951953614e-18 0.0049287528490963295" rpy="0 0 0"/>
    <mass value="0.04920458416046905"/>
    <inertia ixx="4e-06" iyy="4e-06" izz="3e-06" ixy="0.0" iyz="-0.0" ixz="0.0"/>
  </inertial>
  <visual>
    <origin xyz="-0.004237 -0.01 -0.127298" rpy="0 0 0"/>
    <geometry>
      <mesh filename="meshes/pinky_m_1.stl" scale="0.001 0.001 0.001"/>
    </geometry>
    <material name="silver"/>
  </visual>
  <collision>
    <origin xyz="-0.004237 -0.01 -0.127298" rpy="0 0 0"/>
    <geometry>
      <mesh filename="meshes/pinky_m_1.stl" scale="0.001 0.001 0.001"/>
    </geometry>
  </collision>
</link>

<link name="ring_m_1">
  <inertial>
    <origin xyz="-0.0005619692937607473 3.469446951953614e-18 0.00508300874156023" rpy="0 0 0"/>
    <mass value="0.049241706482446516"/>
    <inertia ixx="4e-06" iyy="4e-06" izz="3e-06" ixy="0.0" iyz="-0.0" ixz="0.0"/>
  </inertial>
  <visual>
    <origin xyz="-0.029841 -0.01 -0.158411" rpy="0 0 0"/>
    <geometry>
      <mesh filename="meshes/ring_m_1.stl" scale="0.001 0.001 0.001"/>
    </geometry>
    <material name="silver"/>
  </visual>
  <collision>
    <origin xyz="-0.029841 -0.01 -0.158411" rpy="0 0 0"/>
    <geometry>
      <mesh filename="meshes/ring_m_1.stl" scale="0.001 0.001 0.001"/>
    </geometry>
  </collision>
</link>

<link name="middle_m_1">
  <inertial>
    <origin xyz="0.0005031145863712769 -8.673617379884035e-18 0.007692871761193182" rpy="0 0 0"/>
    <mass value="0.061924838415061606"/>
    <inertia ixx="6e-06" iyy="6e-06" izz="3e-06" ixy="-0.0" iyz="-0.0" ixz="-0.0"/>
  </inertial>
  <visual>
    <origin xyz="-0.056826 -0.01 -0.168524" rpy="0 0 0"/>
    <geometry>
      <mesh filename="meshes/middle_m_1.stl" scale="0.001 0.001 0.001"/>
    </geometry>
    <material name="silver"/>
  </visual>
  <collision>
    <origin xyz="-0.056826 -0.01 -0.168524" rpy="0 0 0"/>
    <geometry>
      <mesh filename="meshes/middle_m_1.stl" scale="0.001 0.001 0.001"/>
    </geometry>
  </collision>
</link>

<link name="index_m_1">
  <inertial>
    <origin xyz="0.0009980536112661614 -4.978656376053436e-16 0.005007542417008626" rpy="0 0 0"/>
    <mass value="0.04922354216380428"/>
    <inertia ixx="4e-06" iyy="4e-06" izz="3e-06" ixy="0.0" iyz="0.0" ixz="-0.0"/>
  </inertial>
  <visual>
    <origin xyz="-0.083841 -0.01 -0.157981" rpy="0 0 0"/>
    <geometry>
      <mesh filename="meshes/index_m_1.stl" scale="0.001 0.001 0.001"/>
    </geometry>
    <material name="silver"/>
  </visual>
  <collision>
    <origin xyz="-0.083841 -0.01 -0.157981" rpy="0 0 0"/>
    <geometry>
      <mesh filename="meshes/index_m_1.stl" scale="0.001 0.001 0.001"/>
    </geometry>
  </collision>
</link>

<link name="pinky_t_1">
  <inertial>
    <origin xyz="-0.0015140707748512415 -4.704998910779953e-06 0.005739342394943142" rpy="0 0 0"/>
    <mass value="0.054506879752136375"/>
    <inertia ixx="4e-06" iyy="4e-06" izz="3e-06" ixy="-0.0" iyz="0.0" ixz="0.0"/>
  </inertial>
  <visual>
    <origin xyz="0.002208 -0.01 -0.15173" rpy="0 0 0"/>
    <geometry>
      <mesh filename="meshes/pinky_t_1.stl" scale="0.001 0.001 0.001"/>
    </geometry>
    <material name="silver"/>
  </visual>
  <collision>
    <origin xyz="0.002208 -0.01 -0.15173" rpy="0 0 0"/>
    <geometry>
      <mesh filename="meshes/pinky_t_1.stl" scale="0.001 0.001 0.001"/>
    </geometry>
  </collision>
</link>

<link name="ring_t_1">
  <inertial>
    <origin xyz="-0.0006519024259250064 -4.704998910783423e-06 0.005898879937333151" rpy="0 0 0"/>
    <mass value="0.05450687975213653"/>
    <inertia ixx="4e-06" iyy="4e-06" izz="3e-06" ixy="-0.0" iyz="0.0" ixz="0.0"/>
  </inertial>
  <visual>
    <origin xyz="-0.027044 -0.01 -0.183715" rpy="0 0 0"/>
    <geometry>
      <mesh filename="meshes/ring_t_1.stl" scale="0.001 0.001 0.001"/>
    </geometry>
    <material name="silver"/>
  </visual>
  <collision>
    <origin xyz="-0.027044 -0.01 -0.183715" rpy="0 0 0"/>
    <geometry>
      <mesh filename="meshes/ring_t_1.stl" scale="0.001 0.001 0.001"/>
    </geometry>
  </collision>
</link>

<link name="middle_t_1">
  <inertial>
    <origin xyz="0.0006265899996844779 -3.549266068552867e-06 0.00958001045144563" rpy="0 0 0"/>
    <mass value="0.07225572975213648"/>
    <inertia ixx="8e-06" iyy="8e-06" izz="4e-06" ixy="0.0" iyz="0.0" ixz="-0.0"/>
  </inertial>
  <visual>
    <origin xyz="-0.058817 -0.01 -0.198944" rpy="0 0 0"/>
    <geometry>
      <mesh filename="meshes/middle_t_1.stl" scale="0.001 0.001 0.001"/>
    </geometry>
    <material name="silver"/>
  </visual>
  <collision>
    <origin xyz="-0.058817 -0.01 -0.198944" rpy="0 0 0"/>
    <geometry>
      <mesh filename="meshes/middle_t_1.stl" scale="0.001 0.001 0.001"/>
    </geometry>
  </collision>
</link>

<link name="index_t_1">
  <inertial>
    <origin xyz="0.001159259354610212 -4.704998910717503e-06 0.0058209981672522615" rpy="0 0 0"/>
    <mass value="0.05450687975213661"/>
    <inertia ixx="4e-06" iyy="4e-06" izz="3e-06" ixy="0.0" iyz="0.0" ixz="-0.0"/>
  </inertial>
  <visual>
    <origin xyz="-0.088798 -0.01 -0.182857" rpy="0 0 0"/>
    <geometry>
      <mesh filename="meshes/index_t_1.stl" scale="0.001 0.001 0.001"/>
    </geometry>
    <material name="silver"/>
  </visual>
  <collision>
    <origin xyz="-0.088798 -0.01 -0.182857" rpy="0 0 0"/>
    <geometry>
      <mesh filename="meshes/index_t_1.stl" scale="0.001 0.001 0.001"/>
    </geometry>
  </collision>
</link>

<link name="thumb_b_1">
  <inertial>
    <origin xyz="0.012352961379988522 2.0643209364124004e-16 0.003157467947648193" rpy="0 0 0"/>
    <mass value="0.061845067027587894"/>
    <inertia ixx="5e-06" iyy="7e-06" izz="4e-06" ixy="-0.0" iyz="-0.0" ixz="-1e-06"/>
  </inertial>
  <visual>
    <origin xyz="-0.0835 -0.01 -0.050246" rpy="0 0 0"/>
    <geometry>
      <mesh filename="meshes/thumb_b_1.stl" scale="0.001 0.001 0.001"/>
    </geometry>
    <material name="silver"/>
  </visual>
  <collision>
    <origin xyz="-0.0835 -0.01 -0.050246" rpy="0 0 0"/>
    <geometry>
      <mesh filename="meshes/thumb_b_1.stl" scale="0.001 0.001 0.001"/>
    </geometry>
  </collision>
</link>

<link name="thumb_m_1">
  <inertial>
    <origin xyz="0.004673283081426199 -8.424120570426838e-06 0.005791809590895147" rpy="0 0 0"/>
    <mass value="0.07376017339121935"/>
    <inertia ixx="6e-06" iyy="8e-06" izz="6e-06" ixy="0.0" iyz="0.0" ixz="-1e-06"/>
  </inertial>
  <visual>
    <origin xyz="-0.111005 -0.01 -0.072075" rpy="0 0 0"/>
    <geometry>
      <mesh filename="meshes/thumb_m_1.stl" scale="0.001 0.001 0.001"/>
    </geometry>
    <material name="silver"/>
  </visual>
  <collision>
    <origin xyz="-0.111005 -0.01 -0.072075" rpy="0 0 0"/>
    <geometry>
      <mesh filename="meshes/thumb_m_1.stl" scale="0.001 0.001 0.001"/>
    </geometry>
  </collision>
</link>

<link name="thumb_t_1">
  <inertial>
    <origin xyz="0.004228379847308478 -1.2130065720986766e-05 0.005240028904204233" rpy="0 0 0"/>
    <mass value="0.07140174665068301"/>
    <inertia ixx="6e-06" iyy="7e-06" izz="5e-06" ixy="0.0" iyz="0.0" ixz="-1e-06"/>
  </inertial>
  <visual>
    <origin xyz="-0.130219 -0.009965 -0.095886" rpy="0 0 0"/>
    <geometry>
      <mesh filename="meshes/thumb_t_1.stl" scale="0.001 0.001 0.001"/>
    </geometry>
    <material name="silver"/>
  </visual>
  <collision>
    <origin xyz="-0.130219 -0.009965 -0.095886" rpy="0 0 0"/>
    <geometry>
      <mesh filename="meshes/thumb_t_1.stl" scale="0.001 0.001 0.001"/>
    </geometry>
  </collision>
</link>

<link name="palm_1">
  <inertial>
    <origin xyz="0.0032614485400721815 4.189956278299531e-06 0.07150272467461033" rpy="0 0 0"/>
    <mass value="1.38871857421675"/>
    <inertia ixx="0.00168" iyy="0.002324" izz="0.000734" ixy="-0.0" iyz="-0.0" ixz="-0.000118"/>
  </inertial>
  <visual>
    <origin xyz="-0.04108 -0.01 0.015169" rpy="0 0 0"/>
    <geometry>
      <mesh filename="meshes/palm_1.stl" scale="0.001 0.001 0.001"/>
    </geometry>
    <material name="silver"/>
  </visual>
  <collision>
    <origin xyz="-0.04108 -0.01 0.015169" rpy="0 0 0"/>
    <geometry>
      <mesh filename="meshes/palm_1.stl" scale="0.001 0.001 0.001"/>
    </geometry>
  </collision>
</link>

<link name="forearm_v1_1">
  <inertial>
    <origin xyz="-3.5992262806955333e-07 2.3245294578089215e-16 0.12668329616658985" rpy="0 0 0"/>
    <mass value="5.932990460342234"/>
    <inertia ixx="0.046358" iyy="0.046064" izz="0.002765" ixy="-0.0" iyz="-0.0" ixz="0.0"/>
  </inertial>
  <visual>
    <origin xyz="-0.04108 -0.01 0.324" rpy="0 0 0"/>
    <geometry>
      <mesh filename="meshes/forearm_v1_1.stl" scale="0.001 0.001 0.001"/>
    </geometry>
    <material name="silver"/>
  </visual>
  <collision>
    <origin xyz="-0.04108 -0.01 0.324" rpy="0 0 0"/>
    <geometry>
      <mesh filename="meshes/forearm_v1_1.stl" scale="0.001 0.001 0.001"/>
    </geometry>
  </collision>
</link>

<link name="elbow_v1_1">
  <inertial>
    <origin xyz="-3.5992262805567554e-07 3.469446951953614e-18 4.5675716542348255e-09" rpy="0 0 0"/>
    <mass value="4.910549497212174"/>
    <inertia ixx="0.007393" iyy="0.007104" izz="0.007022" ixy="-0.0" iyz="0.0" ixz="0.0"/>
  </inertial>
  <visual>
    <origin xyz="-0.04108 -0.01 0.369" rpy="0 0 0"/>
    <geometry>
      <mesh filename="meshes/elbow_v1_1.stl" scale="0.001 0.001 0.001"/>
    </geometry>
    <material name="silver"/>
  </visual>
  <collision>
    <origin xyz="-0.04108 -0.01 0.369" rpy="0 0 0"/>
    <geometry>
      <mesh filename="meshes/elbow_v1_1.stl" scale="0.001 0.001 0.001"/>
    </geometry>
  </collision>
</link>

<link name="upperarm_v1_1">
  <inertial>
    <origin xyz="-3.5992262804873665e-07 -2.6020852139652106e-17 0.18604688252252033" rpy="0 0 0"/>
    <mass value="38.00597131962047"/>
    <inertia ixx="0.581944" iyy="0.598368" izz="0.092438" ixy="-0.0" iyz="0.0" ixz="-0.0"/>
  </inertial>
  <visual>
    <origin xyz="-0.04108 -0.01 0.789" rpy="0 0 0"/>
    <geometry>
      <mesh filename="meshes/upperarm_v1_1.stl" scale="0.001 0.001 0.001"/>
    </geometry>
    <material name="silver"/>
  </visual>
  <collision>
    <origin xyz="-0.04108 -0.01 0.789" rpy="0 0 0"/>
    <geometry>
      <mesh filename="meshes/upperarm_v1_1.stl" scale="0.001 0.001 0.001"/>
    </geometry>
  </collision>
</link>

<link name="shoulderjoint_v1_1">
  <inertial>
    <origin xyz="-3.5992262804873665e-07 3.1012552910436586e-07 0.08461479599344168" rpy="0 0 0"/>
    <mass value="16.084566019701764"/>
    <inertia ixx="0.093267" iyy="0.086747" izz="0.033471" ixy="-0.0" iyz="0.0" ixz="-0.0"/>
  </inertial>
  <visual>
    <origin xyz="-0.04108 -0.01 0.969" rpy="0 0 0"/>
    <geometry>
      <mesh filename="meshes/shoulderjoint_v1_1.stl" scale="0.001 0.001 0.001"/>
    </geometry>
    <material name="silver"/>
  </visual>
  <collision>
    <origin xyz="-0.04108 -0.01 0.969" rpy="0 0 0"/>
    <geometry>
      <mesh filename="meshes/shoulderjoint_v1_1.stl" scale="0.001 0.001 0.001"/>
    </geometry>
  </collision>
</link>

<joint name="Revolute 7" type="revolute">
  <origin xyz="-0.031546 0.0 0.122385" rpy="0 0 0"/>
  <parent link="palm_1"/>
  <child link="pinky_b_1"/>
  <axis xyz="0.966925 0.0 0.255062"/>
  <limit upper="1.570796" lower="0.0" effort="100" velocity="100"/>
</joint>

<joint name="Revolute 8" type="revolute">
  <origin xyz="-0.007344 0.0 0.138337" rpy="0 0 0"/>
  <parent link="palm_1"/>
  <child link="ring_b_1"/>
  <axis xyz="0.993947 0.0 0.109857"/>
  <limit upper="1.570796" lower="0.0" effort="100" velocity="100"/>
</joint>

<joint name="Revolute 9" type="revolute">
  <origin xyz="0.013097 0.0 0.143294" rpy="0 0 0"/>
  <parent link="palm_1"/>
  <child link="middle_b_1"/>
  <axis xyz="0.997865 0.0 -0.065309"/>
  <limit upper="1.570796" lower="0.0" effort="100" velocity="100"/>
</joint>

<joint name="Revolute 10" type="revolute">
  <origin xyz="0.035851 0.0 0.138467" rpy="0 0 0"/>
  <parent link="palm_1"/>
  <child link="index_b_1"/>
  <axis xyz="0.980725 0.0 -0.195393"/>
  <limit upper="1.570796" lower="0.0" effort="100" velocity="100"/>
</joint>

<joint name="Revolute 11" type="revolute">
  <origin xyz="-0.005297 0.0 0.020082" rpy="0 0 0"/>
  <parent link="pinky_b_1"/>
  <child link="pinky_m_1"/>
  <axis xyz="0.966925 0.0 0.255062"/>
  <limit upper="1.570796" lower="0.0" effort="100" velocity="100"/>
</joint>

<joint name="Revolute 12" type="revolute">
  <origin xyz="-0.003895 0.0 0.035243" rpy="0 0 0"/>
  <parent link="ring_b_1"/>
  <child link="ring_m_1"/>
  <axis xyz="0.993947 0.0 0.109857"/>
  <limit upper="1.570796" lower="0.0" effort="100" velocity="100"/>
</joint>

<joint name="Revolute 13" type="revolute">
  <origin xyz="0.002649 0.0 0.040399" rpy="0 0 0"/>
  <parent link="middle_b_1"/>
  <child link="middle_m_1"/>
  <axis xyz="0.997865 -0.0 -0.065309"/>
  <limit upper="1.570796" lower="0.0" effort="100" velocity="100"/>
</joint>

<joint name="Revolute 14" type="revolute">
  <origin xyz="0.00691 0.0 0.034683" rpy="0 0 0"/>
  <parent link="index_b_1"/>
  <child link="index_m_1"/>
  <axis xyz="0.980725 0.0 -0.195393"/>
  <limit upper="1.570796" lower="0.0" effort="100" velocity="100"/>
</joint>

<joint name="Revolute 15" type="revolute">
  <origin xyz="-0.006445 0.0 0.024432" rpy="0 0 0"/>
  <parent link="pinky_m_1"/>
  <child link="pinky_t_1"/>
  <axis xyz="0.966925 0.0 0.255062"/>
  <limit upper="1.570796" lower="0.0" effort="100" velocity="100"/>
</joint>

<joint name="Revolute 16" type="revolute">
  <origin xyz="-0.002797 0.0 0.025304" rpy="0 0 0"/>
  <parent link="ring_m_1"/>
  <child link="ring_t_1"/>
  <axis xyz="0.993947 0.0 0.109857"/>
  <limit upper="1.570796" lower="0.0" effort="100" velocity="100"/>
</joint>

<joint name="Revolute 17" type="revolute">
  <origin xyz="0.001991 0.0 0.03042" rpy="0 0 0"/>
  <parent link="middle_m_1"/>
  <child link="middle_t_1"/>
  <axis xyz="0.997865 0.0 -0.065309"/>
  <limit upper="1.570796" lower="0.0" effort="100" velocity="100"/>
</joint>

<joint name="Revolute 18" type="revolute">
  <origin xyz="0.004957 0.0 0.024876" rpy="0 0 0"/>
  <parent link="index_m_1"/>
  <child link="index_t_1"/>
  <axis xyz="0.980725 0.0 -0.195393"/>
  <limit upper="1.570796" lower="0.0" effort="100" velocity="100"/>
</joint>

<joint name="Revolute 19" type="revolute">
  <origin xyz="0.04242 0.0 0.065415" rpy="0 0 0"/>
  <parent link="palm_1"/>
  <child link="thumb_b_1"/>
  <axis xyz="-0.0 0.0 -1.0"/>
  <limit upper="1.047198" lower="0.0" effort="100" velocity="100"/>
</joint>

<joint name="Revolute 20" type="revolute">
  <origin xyz="0.027505 0.0 0.021829" rpy="0 0 0"/>
  <parent link="thumb_b_1"/>
  <child link="thumb_m_1"/>
  <axis xyz="-0.778222 0.0 0.627989"/>
  <limit upper="0.0" lower="-1.570796" effort="100" velocity="100"/>
</joint>

<joint name="Revolute 21" type="revolute">
  <origin xyz="0.019214 -3.5e-05 0.023811" rpy="0 0 0"/>
  <parent link="thumb_m_1"/>
  <child link="thumb_t_1"/>
  <axis xyz="-0.778222 -0.0 0.627989"/>
  <limit upper="0.0" lower="-1.570796" effort="100" velocity="100"/>
</joint>

<joint name="Revolute 23" type="revolute">
  <origin xyz="0.0 0.0 0.308831" rpy="0 0 0"/>
  <parent link="forearm_v1_1"/>
  <child link="palm_1"/>
  <axis xyz="-1.0 0.0 0.0"/>
  <limit upper="1.570796" lower="-1.570796" effort="100" velocity="100"/>
</joint>

<joint name="Revolute 24" type="revolute">
  <origin xyz="0.0 0.0 0.045" rpy="0 0 0"/>
  <parent link="elbow_v1_1"/>
  <child link="forearm_v1_1"/>
  <axis xyz="0.0 0.0 1.0"/>
  <limit upper="0.0" lower="-3.141593" effort="100" velocity="100"/>
</joint>

<joint name="Revolute 25" type="revolute">
  <origin xyz="0.0 0.0 0.42" rpy="0 0 0"/>
  <parent link="upperarm_v1_1"/>
  <child link="elbow_v1_1"/>
  <axis xyz="1.0 0.0 0.0"/>
  <limit upper="0.0" lower="-2.007129" effort="100" velocity="100"/>
</joint>

<joint name="Revolute 26" type="revolute">
  <origin xyz="0.0 0.0 0.18" rpy="0 0 0"/>
  <parent link="shoulderjoint_v1_1"/>
  <child link="upperarm_v1_1"/>
  <axis xyz="1.0 0.0 0.0"/>
  <limit upper="1.570796" lower="-1.570796" effort="100" velocity="100"/>
</joint>

<joint name="Revolute 27" type="revolute">
  <origin xyz="0.04108 0.01 -0.969" rpy="0 0 0"/>
  <parent link="base_link"/>
  <child link="shoulderjoint_v1_1"/>
  <axis xyz="0.0 0.0 1.0"/>
  <limit upper="3.14" lower="-3.14" effort="100" velocity="100"/>
</joint>

</robot>
